package matt.lyoko.world;

import java.util.Random;

import net.minecraft.block.Block;
import net.minecraft.world.World;
import net.minecraft.world.gen.feature.WorldGenerator;
import matt.lyoko.*;

public class StructureTower extends WorldGenerator
{
	public StructureTower() { }
	
	 protected int[] GetValidSpawnBlocks()
	 {
	  return new int[] { CodeLyoko.Grass.blockID, CodeLyoko.Stone.blockID, CodeLyoko.Sand.blockID, CodeLyoko.Ice.blockID, CodeLyoko.Carthage.blockID };
	 }
	 
	 public boolean LocationIsValidSpawn(World world, int i, int j, int k)
	 {
	  int distanceToAir = 0;
	  int checkID = world.getBlockId(i, j, k);
	  
	  while (checkID != 0)
	  {
	   distanceToAir++;
	   checkID = world.getBlockId(i, j + distanceToAir, k);
	  }
	  
	  if (distanceToAir > 0)
	  {
	   return false;
	  }
	  j += distanceToAir - 1;
	  
	  int blockID = world.getBlockId(i, j, k);
	  int blockIDAbove = world.getBlockId(i, j + 1, k);
	  int blockIDBelow = world.getBlockId(i, j - 1, k);
	  for (int x : GetValidSpawnBlocks())
	  {
	   if (blockIDAbove != 0)
	   {
	    return false;
	   }
	   if (blockID == x)
	   {
	    return true;
	   } else if (blockID == Block.snow.blockID && blockIDBelow == x)
	   {
	    return true;
	   }
	  }
	  return false;
	 }
	 

	public boolean generate(World world, Random rand, int i, int j, int k)
	{
		// check that each corner is one of the valid spawn blocks
		if (!LocationIsValidSpawn(world, i, j, k) || !LocationIsValidSpawn(world, i + 4, j, k) || !LocationIsValidSpawn(world, i + 4, j, k + 4) || !LocationIsValidSpawn(world, i, j, k + 4))
		{
			return false;
		}
		
		world.setBlock(i + 0, j + 0, k + 1, CodeLyoko.TowerBase.blockID);
		world.setBlock(i + 0, j + 0, k + 2, CodeLyoko.TowerBase.blockID);
		world.setBlock(i + 0, j + 0, k + 3, CodeLyoko.TowerBase.blockID);
		world.setBlock(i + 0, j + 0, k + 4, CodeLyoko.TowerBase.blockID);
		world.setBlock(i + 0, j + 0, k + 5, CodeLyoko.TowerBase.blockID);
		world.setBlock(i + 0, j + 1, k + 1, CodeLyoko.TowerBase.blockID);
		world.setBlock(i + 0, j + 1, k + 2, CodeLyoko.TowerBase.blockID);
		world.setBlock(i + 0, j + 1, k + 3, CodeLyoko.TowerBase.blockID);
		world.setBlock(i + 0, j + 1, k + 4, CodeLyoko.TowerBase.blockID);
		world.setBlock(i + 0, j + 1, k + 5, CodeLyoko.TowerBase.blockID);
		world.setBlock(i + 0, j + 2, k + 1, CodeLyoko.TowerBase.blockID);
		world.setBlock(i + 0, j + 2, k + 2, CodeLyoko.TowerBase.blockID);
		world.setBlock(i + 0, j + 2, k + 3, CodeLyoko.TowerBase.blockID);
		world.setBlock(i + 0, j + 2, k + 4, CodeLyoko.TowerBase.blockID);
		world.setBlock(i + 0, j + 2, k + 5, CodeLyoko.TowerBase.blockID);
		world.setBlock(i + 0, j + 3, k + 1, CodeLyoko.TowerBase.blockID);
		world.setBlock(i + 0, j + 3, k + 2, CodeLyoko.TowerBase.blockID);
		world.setBlock(i + 0, j + 3, k + 3, CodeLyoko.TowerBase.blockID);
		world.setBlock(i + 0, j + 3, k + 4, CodeLyoko.TowerBase.blockID);
		world.setBlock(i + 0, j + 3, k + 5, CodeLyoko.TowerBase.blockID);
		world.setBlock(i + 0, j + 4, k + 1, CodeLyoko.TowerBase.blockID);
		world.setBlock(i + 0, j + 4, k + 2, CodeLyoko.TowerBase.blockID);
		world.setBlock(i + 0, j + 4, k + 3, CodeLyoko.TowerBase.blockID);
		world.setBlock(i + 0, j + 4, k + 4, CodeLyoko.TowerBase.blockID);
		world.setBlock(i + 0, j + 4, k + 5, CodeLyoko.TowerBase.blockID);
		world.setBlock(i + 0, j + 5, k + 1, CodeLyoko.TowerBase.blockID);
		world.setBlock(i + 0, j + 5, k + 2, CodeLyoko.TowerBase.blockID);
		world.setBlock(i + 0, j + 5, k + 3, CodeLyoko.TowerBase.blockID);
		world.setBlock(i + 0, j + 5, k + 4, CodeLyoko.TowerBase.blockID);
		world.setBlock(i + 0, j + 5, k + 5, CodeLyoko.TowerBase.blockID);
		world.setBlock(i + 0, j + 6, k + 1, CodeLyoko.TowerBase.blockID);
		world.setBlock(i + 0, j + 6, k + 2, CodeLyoko.TowerBase.blockID);
		world.setBlock(i + 0, j + 6, k + 3, CodeLyoko.TowerBase.blockID);
		world.setBlock(i + 0, j + 6, k + 4, CodeLyoko.TowerBase.blockID);
		world.setBlock(i + 0, j + 6, k + 5, CodeLyoko.TowerBase.blockID);
		world.setBlock(i + 0, j + 7, k + 1, CodeLyoko.TowerBase.blockID);
		world.setBlock(i + 0, j + 7, k + 2, CodeLyoko.TowerBase.blockID);
		world.setBlock(i + 0, j + 7, k + 3, CodeLyoko.TowerBase.blockID);
		world.setBlock(i + 0, j + 7, k + 4, CodeLyoko.TowerBase.blockID);
		world.setBlock(i + 0, j + 7, k + 5, CodeLyoko.TowerBase.blockID);
		world.setBlock(i + 0, j + 8, k + 1, CodeLyoko.TowerBlock.blockID);
		world.setBlock(i + 0, j + 8, k + 2, CodeLyoko.TowerBlock.blockID);
		world.setBlock(i + 0, j + 8, k + 3, CodeLyoko.TowerBlock.blockID);
		world.setBlock(i + 0, j + 8, k + 4, CodeLyoko.TowerBlock.blockID);
		world.setBlock(i + 0, j + 8, k + 5, CodeLyoko.TowerBlock.blockID);
		world.setBlock(i + 0, j + 9, k + 1, CodeLyoko.TowerBlock.blockID);
		world.setBlock(i + 0, j + 9, k + 2, CodeLyoko.TowerBlock.blockID);
		world.setBlock(i + 0, j + 9, k + 3, CodeLyoko.TowerBlock.blockID);
		world.setBlock(i + 0, j + 9, k + 4, CodeLyoko.TowerBlock.blockID);
		world.setBlock(i + 0, j + 9, k + 5, CodeLyoko.TowerBlock.blockID);
		world.setBlock(i + 0, j + 10, k + 1, CodeLyoko.TowerBlock.blockID);
		world.setBlock(i + 0, j + 10, k + 2, CodeLyoko.TowerBlock.blockID);
		world.setBlock(i + 0, j + 10, k + 3, CodeLyoko.TowerBlock.blockID);
		world.setBlock(i + 0, j + 10, k + 4, CodeLyoko.TowerBlock.blockID);
		world.setBlock(i + 0, j + 10, k + 5, CodeLyoko.TowerBlock.blockID);
		world.setBlock(i + 0, j + 11, k + 1, CodeLyoko.TowerBlock.blockID);
		world.setBlock(i + 0, j + 11, k + 2, CodeLyoko.TowerBlock.blockID);
		world.setBlock(i + 0, j + 11, k + 3, CodeLyoko.TowerBlock.blockID);
		world.setBlock(i + 0, j + 11, k + 4, CodeLyoko.TowerBlock.blockID);
		world.setBlock(i + 0, j + 11, k + 5, CodeLyoko.TowerBlock.blockID);
		world.setBlock(i + 0, j + 12, k + 1, CodeLyoko.TowerBlock.blockID);
		world.setBlock(i + 0, j + 12, k + 2, CodeLyoko.TowerBlock.blockID);
		world.setBlock(i + 0, j + 12, k + 3, CodeLyoko.TowerBlock.blockID);
		world.setBlock(i + 0, j + 12, k + 4, CodeLyoko.TowerBlock.blockID);
		world.setBlock(i + 0, j + 12, k + 5, CodeLyoko.TowerBlock.blockID);
		world.setBlock(i + 0, j + 13, k + 1, CodeLyoko.TowerBlock.blockID);
		world.setBlock(i + 0, j + 13, k + 2, CodeLyoko.TowerBlock.blockID);
		world.setBlock(i + 0, j + 13, k + 3, CodeLyoko.TowerBlock.blockID);
		world.setBlock(i + 0, j + 13, k + 4, CodeLyoko.TowerBlock.blockID);
		world.setBlock(i + 0, j + 13, k + 5, CodeLyoko.TowerBlock.blockID);
		world.setBlock(i + 0, j + 14, k + 1, CodeLyoko.TowerBlock.blockID);
		world.setBlock(i + 0, j + 14, k + 2, CodeLyoko.TowerBlock.blockID);
		world.setBlock(i + 0, j + 14, k + 3, CodeLyoko.TowerBlock.blockID);
		world.setBlock(i + 0, j + 14, k + 4, CodeLyoko.TowerBlock.blockID);
		world.setBlock(i + 0, j + 14, k + 5, CodeLyoko.TowerBlock.blockID);
		world.setBlock(i + 0, j + 15, k + 1, CodeLyoko.TowerBlock.blockID);
		world.setBlock(i + 0, j + 15, k + 2, CodeLyoko.TowerBlock.blockID);
		world.setBlock(i + 0, j + 15, k + 3, CodeLyoko.TowerBlock.blockID);
		world.setBlock(i + 0, j + 15, k + 4, CodeLyoko.TowerBlock.blockID);
		world.setBlock(i + 0, j + 15, k + 5, CodeLyoko.TowerBlock.blockID);
		world.setBlock(i + 0, j + 16, k + 1, CodeLyoko.TowerBlock.blockID);
		world.setBlock(i + 0, j + 16, k + 2, CodeLyoko.TowerBlock.blockID);
		world.setBlock(i + 0, j + 16, k + 3, CodeLyoko.TowerBlock.blockID);
		world.setBlock(i + 0, j + 16, k + 4, CodeLyoko.TowerBlock.blockID);
		world.setBlock(i + 0, j + 16, k + 5, CodeLyoko.TowerBlock.blockID);
		world.setBlock(i + 1, j + 0, k + 0, CodeLyoko.TowerBase.blockID);
		world.setBlock(i + 1, j + 0, k + 1, CodeLyoko.TowerBase.blockID);
		world.setBlock(i + 1, j + 0, k + 2, CodeLyoko.TowerBase.blockID);
		world.setBlock(i + 1, j + 0, k + 3, CodeLyoko.TowerBase.blockID);
		world.setBlock(i + 1, j + 0, k + 4, CodeLyoko.TowerBase.blockID);
		world.setBlock(i + 1, j + 0, k + 5, CodeLyoko.TowerBase.blockID);
		world.setBlock(i + 1, j + 0, k + 6, CodeLyoko.TowerBase.blockID);
		world.setBlock(i + 1, j + 1, k + 0, CodeLyoko.TowerBase.blockID);
		world.setBlock(i + 1, j + 1, k + 6, CodeLyoko.TowerBase.blockID);
		world.setBlock(i + 1, j + 2, k + 0, CodeLyoko.TowerBase.blockID);
		world.setBlock(i + 1, j + 2, k + 6, CodeLyoko.TowerBase.blockID);
		world.setBlock(i + 1, j + 3, k + 0, CodeLyoko.TowerBase.blockID);
		world.setBlock(i + 1, j + 3, k + 6, CodeLyoko.TowerBase.blockID);
		world.setBlock(i + 1, j + 4, k + 0, CodeLyoko.TowerBase.blockID);
		world.setBlock(i + 1, j + 4, k + 6, CodeLyoko.TowerBase.blockID);
		world.setBlock(i + 1, j + 5, k + 0, CodeLyoko.TowerBase.blockID);
		world.setBlock(i + 1, j + 5, k + 6, CodeLyoko.TowerBase.blockID);
		world.setBlock(i + 1, j + 6, k + 0, CodeLyoko.TowerBase.blockID);
		world.setBlock(i + 1, j + 6, k + 6, CodeLyoko.TowerBase.blockID);
		world.setBlock(i + 1, j + 7, k + 0, CodeLyoko.TowerBase.blockID);
		world.setBlock(i + 1, j + 7, k + 6, CodeLyoko.TowerBase.blockID);
		world.setBlock(i + 1, j + 8, k + 0, CodeLyoko.TowerBlock.blockID);
		world.setBlock(i + 1, j + 8, k + 1, CodeLyoko.DigitalSeaBlock.blockID);
		world.setBlock(i + 1, j + 8, k + 2, CodeLyoko.TowerBase.blockID);
		world.setBlock(i + 1, j + 8, k + 3, CodeLyoko.DigitalSeaBlock.blockID);
		world.setBlock(i + 1, j + 8, k + 4, CodeLyoko.TowerBase.blockID);
		world.setBlock(i + 1, j + 8, k + 5, CodeLyoko.DigitalSeaBlock.blockID);
		world.setBlock(i + 1, j + 8, k + 6, CodeLyoko.TowerBlock.blockID);
		world.setBlock(i + 1, j + 9, k + 0, CodeLyoko.TowerBlock.blockID);
		world.setBlock(i + 1, j + 9, k + 2, CodeLyoko.DigitalSeaBlock.blockID);
		world.setBlock(i + 1, j + 9, k + 3, CodeLyoko.TowerBase.blockID);
		world.setBlock(i + 1, j + 9, k + 4, CodeLyoko.DigitalSeaBlock.blockID);
		world.setBlock(i + 1, j + 9, k + 6, CodeLyoko.TowerBlock.blockID);
		world.setBlock(i + 1, j + 10, k + 0, CodeLyoko.TowerBlock.blockID);
		world.setBlock(i + 1, j + 10, k + 1, CodeLyoko.DigitalSeaBlock.blockID);
		world.setBlock(i + 1, j + 10, k + 2, CodeLyoko.TowerBase.blockID);
		world.setBlock(i + 1, j + 10, k + 3, CodeLyoko.DigitalSeaBlock.blockID);
		world.setBlock(i + 1, j + 10, k + 4, CodeLyoko.TowerBase.blockID);
		world.setBlock(i + 1, j + 10, k + 5, CodeLyoko.DigitalSeaBlock.blockID);
		world.setBlock(i + 1, j + 10, k + 6, CodeLyoko.TowerBlock.blockID);
		world.setBlock(i + 1, j + 11, k + 0, CodeLyoko.TowerBlock.blockID);
		world.setBlock(i + 1, j + 11, k + 2, CodeLyoko.DigitalSeaBlock.blockID);
		world.setBlock(i + 1, j + 11, k + 3, CodeLyoko.TowerBase.blockID);
		world.setBlock(i + 1, j + 11, k + 4, CodeLyoko.DigitalSeaBlock.blockID);
		world.setBlock(i + 1, j + 11, k + 6, CodeLyoko.TowerBlock.blockID);
		world.setBlock(i + 1, j + 12, k + 0, CodeLyoko.TowerBlock.blockID);
		world.setBlock(i + 1, j + 12, k + 1, CodeLyoko.DigitalSeaBlock.blockID);
		world.setBlock(i + 1, j + 12, k + 2, CodeLyoko.TowerBase.blockID);
		world.setBlock(i + 1, j + 12, k + 3, CodeLyoko.DigitalSeaBlock.blockID);
		world.setBlock(i + 1, j + 12, k + 4, CodeLyoko.TowerBase.blockID);
		world.setBlock(i + 1, j + 12, k + 5, CodeLyoko.DigitalSeaBlock.blockID);
		world.setBlock(i + 1, j + 12, k + 6, CodeLyoko.TowerBlock.blockID);
		world.setBlock(i + 1, j + 13, k + 0, CodeLyoko.TowerBlock.blockID);
		world.setBlock(i + 1, j + 13, k + 2, CodeLyoko.DigitalSeaBlock.blockID);
		world.setBlock(i + 1, j + 13, k + 3, CodeLyoko.TowerBase.blockID);
		world.setBlock(i + 1, j + 13, k + 4, CodeLyoko.DigitalSeaBlock.blockID);
		world.setBlock(i + 1, j + 13, k + 6, CodeLyoko.TowerBlock.blockID);
		world.setBlock(i + 1, j + 14, k + 0, CodeLyoko.TowerBlock.blockID);
		world.setBlock(i + 1, j + 14, k + 1, CodeLyoko.DigitalSeaBlock.blockID);
		world.setBlock(i + 1, j + 14, k + 2, CodeLyoko.TowerBase.blockID);
		world.setBlock(i + 1, j + 14, k + 3, CodeLyoko.DigitalSeaBlock.blockID);
		world.setBlock(i + 1, j + 14, k + 4, CodeLyoko.TowerBase.blockID);
		world.setBlock(i + 1, j + 14, k + 5, CodeLyoko.DigitalSeaBlock.blockID);
		world.setBlock(i + 1, j + 14, k + 6, CodeLyoko.TowerBlock.blockID);
		world.setBlock(i + 1, j + 15, k + 0, CodeLyoko.TowerBlock.blockID);
		world.setBlock(i + 1, j + 15, k + 1, CodeLyoko.TowerBase.blockID);
		world.setBlock(i + 1, j + 15, k + 2, CodeLyoko.DigitalSeaBlock.blockID);
		world.setBlock(i + 1, j + 15, k + 3, CodeLyoko.TowerBase.blockID);
		world.setBlock(i + 1, j + 15, k + 4, CodeLyoko.DigitalSeaBlock.blockID);
		world.setBlock(i + 1, j + 15, k + 5, CodeLyoko.TowerBase.blockID);
		world.setBlock(i + 1, j + 15, k + 6, CodeLyoko.TowerBlock.blockID);
		world.setBlock(i + 1, j + 16, k + 0, CodeLyoko.TowerBlock.blockID);
		world.setBlock(i + 1, j + 16, k + 1, CodeLyoko.TowerBase.blockID);
		world.setBlock(i + 1, j + 16, k + 2, CodeLyoko.TowerBase.blockID);
		world.setBlock(i + 1, j + 16, k + 3, CodeLyoko.TowerBase.blockID);
		world.setBlock(i + 1, j + 16, k + 4, CodeLyoko.TowerBase.blockID);
		world.setBlock(i + 1, j + 16, k + 5, CodeLyoko.TowerBase.blockID);
		world.setBlock(i + 1, j + 16, k + 6, CodeLyoko.TowerBlock.blockID);
		world.setBlock(i + 1, j + 17, k + 1, CodeLyoko.TowerBlock.blockID);
		world.setBlock(i + 1, j + 17, k + 2, CodeLyoko.TowerBlock.blockID);
		world.setBlock(i + 1, j + 17, k + 3, CodeLyoko.TowerBlock.blockID);
		world.setBlock(i + 1, j + 17, k + 4, CodeLyoko.TowerBlock.blockID);
		world.setBlock(i + 1, j + 17, k + 5, CodeLyoko.TowerBlock.blockID);
		world.setBlock(i + 2, j + 0, k + 0, CodeLyoko.TowerBase.blockID);
		world.setBlock(i + 2, j + 0, k + 1, CodeLyoko.TowerBase.blockID);
		world.setBlock(i + 2, j + 0, k + 2, CodeLyoko.TowerBase.blockID);
		world.setBlock(i + 2, j + 0, k + 3, CodeLyoko.TowerBase.blockID);
		world.setBlock(i + 2, j + 0, k + 4, CodeLyoko.TowerBase.blockID);
		world.setBlock(i + 2, j + 0, k + 5, CodeLyoko.TowerBase.blockID);
		world.setBlock(i + 2, j + 0, k + 6, CodeLyoko.TowerBase.blockID);
		world.setBlock(i + 2, j + 1, k + 0, CodeLyoko.TowerBase.blockID);
		world.setBlock(i + 2, j + 1, k + 6, CodeLyoko.TowerBase.blockID);
		world.setBlock(i + 2, j + 2, k + 0, CodeLyoko.TowerBase.blockID);
		world.setBlock(i + 2, j + 2, k + 6, CodeLyoko.TowerBase.blockID);
		world.setBlock(i + 2, j + 3, k + 0, CodeLyoko.TowerBase.blockID);
		world.setBlock(i + 2, j + 3, k + 6, CodeLyoko.TowerBase.blockID);
		world.setBlock(i + 2, j + 4, k + 0, CodeLyoko.TowerBase.blockID);
		world.setBlock(i + 2, j + 4, k + 2, Block.blockLapis.blockID);
		world.setBlock(i + 2, j + 4, k + 3, Block.blockLapis.blockID);
		world.setBlock(i + 2, j + 4, k + 4, Block.blockLapis.blockID);
		world.setBlock(i + 2, j + 4, k + 6, CodeLyoko.TowerBase.blockID);
		world.setBlock(i + 2, j + 5, k + 0, CodeLyoko.TowerBase.blockID);
		world.setBlock(i + 2, j + 5, k + 6, CodeLyoko.TowerBase.blockID);
		world.setBlock(i + 2, j + 6, k + 0, CodeLyoko.TowerBase.blockID);
		world.setBlock(i + 2, j + 6, k + 6, CodeLyoko.TowerBase.blockID);
		world.setBlock(i + 2, j + 7, k + 0, CodeLyoko.TowerBase.blockID);
		world.setBlock(i + 2, j + 7, k + 6, CodeLyoko.TowerBase.blockID);
		world.setBlock(i + 2, j + 8, k + 0, CodeLyoko.TowerBlock.blockID);
		world.setBlock(i + 2, j + 8, k + 1, CodeLyoko.TowerBase.blockID);
		world.setBlock(i + 2, j + 8, k + 5, CodeLyoko.TowerBase.blockID);
		world.setBlock(i + 2, j + 8, k + 6, CodeLyoko.TowerBlock.blockID);
		world.setBlock(i + 2, j + 9, k + 0, CodeLyoko.TowerBlock.blockID);
		world.setBlock(i + 2, j + 9, k + 1, CodeLyoko.DigitalSeaBlock.blockID);
		world.setBlock(i + 2, j + 9, k + 5, CodeLyoko.DigitalSeaBlock.blockID);
		world.setBlock(i + 2, j + 9, k + 6, CodeLyoko.TowerBlock.blockID);
		world.setBlock(i + 2, j + 10, k + 0, CodeLyoko.TowerBlock.blockID);
		world.setBlock(i + 2, j + 10, k + 1, CodeLyoko.TowerBase.blockID);
		world.setBlock(i + 2, j + 10, k + 5, CodeLyoko.TowerBase.blockID);
		world.setBlock(i + 2, j + 10, k + 6, CodeLyoko.TowerBlock.blockID);
		world.setBlock(i + 2, j + 11, k + 0, CodeLyoko.TowerBlock.blockID);
		world.setBlock(i + 2, j + 11, k + 1, CodeLyoko.DigitalSeaBlock.blockID);
		world.setBlock(i + 2, j + 11, k + 5, CodeLyoko.DigitalSeaBlock.blockID);
		world.setBlock(i + 2, j + 11, k + 6, CodeLyoko.TowerBlock.blockID);
		world.setBlock(i + 2, j + 12, k + 0, CodeLyoko.TowerBlock.blockID);
		world.setBlock(i + 2, j + 12, k + 1, CodeLyoko.TowerBase.blockID);
		world.setBlock(i + 2, j + 12, k + 2, Block.blockLapis.blockID);
		world.setBlock(i + 2, j + 12, k + 3, Block.blockLapis.blockID);
		world.setBlock(i + 2, j + 12, k + 4, Block.blockLapis.blockID);
		world.setBlock(i + 2, j + 12, k + 5, CodeLyoko.TowerBase.blockID);
		world.setBlock(i + 2, j + 12, k + 6, CodeLyoko.TowerBlock.blockID);
		world.setBlock(i + 2, j + 13, k + 0, CodeLyoko.TowerBlock.blockID);
		world.setBlock(i + 2, j + 13, k + 1, CodeLyoko.DigitalSeaBlock.blockID);
		world.setBlock(i + 2, j + 13, k + 5, CodeLyoko.DigitalSeaBlock.blockID);
		world.setBlock(i + 2, j + 13, k + 6, CodeLyoko.TowerBlock.blockID);
		world.setBlock(i + 2, j + 14, k + 0, CodeLyoko.TowerBlock.blockID);
		world.setBlock(i + 2, j + 14, k + 1, CodeLyoko.TowerBase.blockID);
		world.setBlock(i + 2, j + 14, k + 5, CodeLyoko.TowerBase.blockID);
		world.setBlock(i + 2, j + 14, k + 6, CodeLyoko.TowerBlock.blockID);
		world.setBlock(i + 2, j + 15, k + 0, CodeLyoko.TowerBlock.blockID);
		world.setBlock(i + 2, j + 15, k + 1, CodeLyoko.DigitalSeaBlock.blockID);
		world.setBlock(i + 2, j + 15, k + 5, CodeLyoko.DigitalSeaBlock.blockID);
		world.setBlock(i + 2, j + 15, k + 6, CodeLyoko.TowerBlock.blockID);
		world.setBlock(i + 2, j + 16, k + 0, CodeLyoko.TowerBlock.blockID);
		world.setBlock(i + 2, j + 16, k + 1, CodeLyoko.TowerBase.blockID);
		world.setBlock(i + 2, j + 16, k + 2, CodeLyoko.TowerBase.blockID);
		world.setBlock(i + 2, j + 16, k + 3, CodeLyoko.TowerBase.blockID);
		world.setBlock(i + 2, j + 16, k + 4, CodeLyoko.TowerBase.blockID);
		world.setBlock(i + 2, j + 16, k + 5, CodeLyoko.TowerBase.blockID);
		world.setBlock(i + 2, j + 16, k + 6, CodeLyoko.TowerBlock.blockID);
		world.setBlock(i + 2, j + 17, k + 1, CodeLyoko.TowerBlock.blockID);
		world.setBlock(i + 2, j + 17, k + 2, CodeLyoko.TowerBlock.blockID);
		world.setBlock(i + 2, j + 17, k + 3, CodeLyoko.TowerBlock.blockID);
		world.setBlock(i + 2, j + 17, k + 4, CodeLyoko.TowerBlock.blockID);
		world.setBlock(i + 2, j + 17, k + 5, CodeLyoko.TowerBlock.blockID);
		world.setBlock(i + 3, j + 0, k + 0, CodeLyoko.TowerBase.blockID);
		world.setBlock(i + 3, j + 0, k + 1, CodeLyoko.TowerBase.blockID);
		world.setBlock(i + 3, j + 0, k + 2, CodeLyoko.TowerBase.blockID);
		world.setBlock(i + 3, j + 0, k + 3, CodeLyoko.TowerBase.blockID);
		world.setBlock(i + 3, j + 0, k + 4, CodeLyoko.TowerBase.blockID);
		world.setBlock(i + 3, j + 0, k + 5, CodeLyoko.TowerBase.blockID);
		world.setBlock(i + 3, j + 0, k + 6, CodeLyoko.TowerBase.blockID);
		world.setBlock(i + 3, j + 1, k + 0, CodeLyoko.TowerBase.blockID);
		world.setBlock(i + 3, j + 1, k + 6, CodeLyoko.TowerBase.blockID);
		world.setBlock(i + 3, j + 2, k + 0, CodeLyoko.TowerBase.blockID);
		world.setBlock(i + 3, j + 2, k + 6, CodeLyoko.TowerBase.blockID);
		world.setBlock(i + 3, j + 3, k + 0, CodeLyoko.TowerBase.blockID);
		world.setBlock(i + 3, j + 3, k + 6, CodeLyoko.TowerBase.blockID);
		world.setBlock(i + 3, j + 4, k + 0, CodeLyoko.TowerBase.blockID);
		world.setBlock(i + 3, j + 4, k + 2, Block.blockLapis.blockID);
		world.setBlock(i + 3, j + 4, k + 3, Block.cloth.blockID);
		world.setBlock(i + 3, j + 4, k + 4, Block.blockLapis.blockID);
		world.setBlock(i + 3, j + 4, k + 6, CodeLyoko.TowerBase.blockID);
		world.setBlock(i + 3, j + 5, k + 0, CodeLyoko.TowerBase.blockID);
		world.setBlock(i + 3, j + 5, k + 6, CodeLyoko.TowerBase.blockID);
		world.setBlock(i + 3, j + 6, k + 0, CodeLyoko.TowerBase.blockID);
		world.setBlock(i + 3, j + 6, k + 6, CodeLyoko.TowerBase.blockID);
		world.setBlock(i + 3, j + 7, k + 0, CodeLyoko.TowerBase.blockID);
		world.setBlock(i + 3, j + 7, k + 6, CodeLyoko.TowerBase.blockID);
		world.setBlock(i + 3, j + 8, k + 0, CodeLyoko.TowerBlock.blockID);
		world.setBlock(i + 3, j + 8, k + 1, CodeLyoko.DigitalSeaBlock.blockID);
		world.setBlock(i + 3, j + 8, k + 5, CodeLyoko.DigitalSeaBlock.blockID);
		world.setBlock(i + 3, j + 8, k + 6, CodeLyoko.TowerBlock.blockID);
		world.setBlock(i + 3, j + 9, k + 0, CodeLyoko.TowerBlock.blockID);
		world.setBlock(i + 3, j + 9, k + 1, CodeLyoko.TowerBase.blockID);
		world.setBlock(i + 3, j + 9, k + 5, CodeLyoko.TowerBase.blockID);
		world.setBlock(i + 3, j + 9, k + 6, CodeLyoko.TowerBlock.blockID);
		world.setBlock(i + 3, j + 10, k + 0, CodeLyoko.TowerBlock.blockID);
		world.setBlock(i + 3, j + 10, k + 1, CodeLyoko.DigitalSeaBlock.blockID);
		world.setBlock(i + 3, j + 10, k + 5, CodeLyoko.DigitalSeaBlock.blockID);
		world.setBlock(i + 3, j + 10, k + 6, CodeLyoko.TowerBlock.blockID);
		world.setBlock(i + 3, j + 11, k + 0, CodeLyoko.TowerBlock.blockID);
		world.setBlock(i + 3, j + 11, k + 1, CodeLyoko.TowerBase.blockID);
		world.setBlock(i + 3, j + 11, k + 5, CodeLyoko.TowerBase.blockID);
		world.setBlock(i + 3, j + 11, k + 6, CodeLyoko.TowerBlock.blockID);
		world.setBlock(i + 3, j + 12, k + 0, CodeLyoko.TowerBlock.blockID);
		world.setBlock(i + 3, j + 12, k + 1, CodeLyoko.DigitalSeaBlock.blockID);
		world.setBlock(i + 3, j + 12, k + 2, Block.blockLapis.blockID);
		world.setBlock(i + 3, j + 12, k + 4, Block.blockLapis.blockID);
		world.setBlock(i + 3, j + 12, k + 5, CodeLyoko.DigitalSeaBlock.blockID);
		world.setBlock(i + 3, j + 12, k + 6, CodeLyoko.TowerBlock.blockID);
		world.setBlock(i + 3, j + 13, k + 0, CodeLyoko.TowerBlock.blockID);
		world.setBlock(i + 3, j + 13, k + 1, CodeLyoko.TowerBase.blockID);
		world.setBlock(i + 3, j + 13, k + 5, CodeLyoko.TowerBase.blockID);
		world.setBlock(i + 3, j + 13, k + 6, CodeLyoko.TowerBlock.blockID);
		world.setBlock(i + 3, j + 14, k + 0, CodeLyoko.TowerBlock.blockID);
		world.setBlock(i + 3, j + 14, k + 1, CodeLyoko.DigitalSeaBlock.blockID);
		world.setBlock(i + 3, j + 14, k + 5, CodeLyoko.DigitalSeaBlock.blockID);
		world.setBlock(i + 3, j + 14, k + 6, CodeLyoko.TowerBlock.blockID);
		world.setBlock(i + 3, j + 15, k + 0, CodeLyoko.TowerBlock.blockID);
		world.setBlock(i + 3, j + 15, k + 1, CodeLyoko.TowerBase.blockID);
		world.setBlock(i + 3, j + 15, k + 5, CodeLyoko.TowerBase.blockID);
		world.setBlock(i + 3, j + 15, k + 6, CodeLyoko.TowerBlock.blockID);
		world.setBlock(i + 3, j + 16, k + 0, CodeLyoko.TowerBlock.blockID);
		world.setBlock(i + 3, j + 16, k + 1, CodeLyoko.TowerBase.blockID);
		world.setBlock(i + 3, j + 16, k + 2, CodeLyoko.TowerBase.blockID);
		world.setBlock(i + 3, j + 16, k + 3, CodeLyoko.TowerBase.blockID);
		world.setBlock(i + 3, j + 16, k + 4, CodeLyoko.TowerBase.blockID);
		world.setBlock(i + 3, j + 16, k + 5, CodeLyoko.TowerBase.blockID);
		world.setBlock(i + 3, j + 16, k + 6, CodeLyoko.TowerBlock.blockID);
		world.setBlock(i + 3, j + 17, k + 1, CodeLyoko.TowerBlock.blockID);
		world.setBlock(i + 3, j + 17, k + 2, CodeLyoko.TowerBlock.blockID);
		world.setBlock(i + 3, j + 17, k + 3, CodeLyoko.TowerBlock.blockID);
		world.setBlock(i + 3, j + 17, k + 4, CodeLyoko.TowerBlock.blockID);
		world.setBlock(i + 3, j + 17, k + 5, CodeLyoko.TowerBlock.blockID);
		world.setBlock(i + 4, j + 0, k + 0, CodeLyoko.TowerBase.blockID);
		world.setBlock(i + 4, j + 0, k + 1, CodeLyoko.TowerBase.blockID);
		world.setBlock(i + 4, j + 0, k + 2, CodeLyoko.TowerBase.blockID);
		world.setBlock(i + 4, j + 0, k + 3, CodeLyoko.TowerBase.blockID);
		world.setBlock(i + 4, j + 0, k + 4, CodeLyoko.TowerBase.blockID);
		world.setBlock(i + 4, j + 0, k + 5, CodeLyoko.TowerBase.blockID);
		world.setBlock(i + 4, j + 0, k + 6, CodeLyoko.TowerBase.blockID);
		world.setBlock(i + 4, j + 1, k + 0, CodeLyoko.TowerBase.blockID);
		world.setBlock(i + 4, j + 1, k + 6, CodeLyoko.TowerBase.blockID);
		world.setBlock(i + 4, j + 2, k + 0, CodeLyoko.TowerBase.blockID);
		world.setBlock(i + 4, j + 2, k + 6, CodeLyoko.TowerBase.blockID);
		world.setBlock(i + 4, j + 3, k + 0, CodeLyoko.TowerBase.blockID);
		world.setBlock(i + 4, j + 3, k + 6, CodeLyoko.TowerBase.blockID);
		world.setBlock(i + 4, j + 4, k + 0, CodeLyoko.TowerBase.blockID);
		world.setBlock(i + 4, j + 4, k + 2, Block.blockLapis.blockID);
		world.setBlock(i + 4, j + 4, k + 3, Block.blockLapis.blockID);
		world.setBlock(i + 4, j + 4, k + 4, Block.blockLapis.blockID);
		world.setBlock(i + 4, j + 4, k + 6, CodeLyoko.TowerBase.blockID);
		world.setBlock(i + 4, j + 5, k + 0, CodeLyoko.TowerBase.blockID);
		world.setBlock(i + 4, j + 5, k + 6, CodeLyoko.TowerBase.blockID);
		world.setBlock(i + 4, j + 6, k + 0, CodeLyoko.TowerBase.blockID);
		world.setBlock(i + 4, j + 6, k + 6, CodeLyoko.TowerBase.blockID);
		world.setBlock(i + 4, j + 7, k + 0, CodeLyoko.TowerBase.blockID);
		world.setBlock(i + 4, j + 7, k + 6, CodeLyoko.TowerBase.blockID);
		world.setBlock(i + 4, j + 8, k + 0, CodeLyoko.TowerBlock.blockID);
		world.setBlock(i + 4, j + 8, k + 1, CodeLyoko.TowerBase.blockID);
		world.setBlock(i + 4, j + 8, k + 5, CodeLyoko.TowerBase.blockID);
		world.setBlock(i + 4, j + 8, k + 6, CodeLyoko.TowerBlock.blockID);
		world.setBlock(i + 4, j + 9, k + 0, CodeLyoko.TowerBlock.blockID);
		world.setBlock(i + 4, j + 9, k + 1, CodeLyoko.DigitalSeaBlock.blockID);
		world.setBlock(i + 4, j + 9, k + 5, CodeLyoko.DigitalSeaBlock.blockID);
		world.setBlock(i + 4, j + 9, k + 6, CodeLyoko.TowerBlock.blockID);
		world.setBlock(i + 4, j + 10, k + 0, CodeLyoko.TowerBlock.blockID);
		world.setBlock(i + 4, j + 10, k + 1, CodeLyoko.TowerBase.blockID);
		world.setBlock(i + 4, j + 10, k + 5, CodeLyoko.TowerBase.blockID);
		world.setBlock(i + 4, j + 10, k + 6, CodeLyoko.TowerBlock.blockID);
		world.setBlock(i + 4, j + 11, k + 0, CodeLyoko.TowerBlock.blockID);
		world.setBlock(i + 4, j + 11, k + 1, CodeLyoko.DigitalSeaBlock.blockID);
		world.setBlock(i + 4, j + 11, k + 5, CodeLyoko.DigitalSeaBlock.blockID);
		world.setBlock(i + 4, j + 11, k + 6, CodeLyoko.TowerBlock.blockID);
		world.setBlock(i + 4, j + 12, k + 0, CodeLyoko.TowerBlock.blockID);
		world.setBlock(i + 4, j + 12, k + 1, CodeLyoko.TowerBase.blockID);
		world.setBlock(i + 4, j + 12, k + 2, Block.blockLapis.blockID);
		world.setBlock(i + 4, j + 12, k + 3, Block.blockLapis.blockID);
		world.setBlock(i + 4, j + 12, k + 4, Block.blockLapis.blockID);
		world.setBlock(i + 4, j + 12, k + 5, CodeLyoko.TowerBase.blockID);
		world.setBlock(i + 4, j + 12, k + 6, CodeLyoko.TowerBlock.blockID);
		world.setBlock(i + 4, j + 13, k + 0, CodeLyoko.TowerBlock.blockID);
		world.setBlock(i + 4, j + 13, k + 1, CodeLyoko.DigitalSeaBlock.blockID);
		world.setBlock(i + 4, j + 13, k + 5, CodeLyoko.DigitalSeaBlock.blockID);
		world.setBlock(i + 4, j + 13, k + 6, CodeLyoko.TowerBlock.blockID);
		world.setBlock(i + 4, j + 14, k + 0, CodeLyoko.TowerBlock.blockID);
		world.setBlock(i + 4, j + 14, k + 1, CodeLyoko.TowerBase.blockID);
		world.setBlock(i + 4, j + 14, k + 5, CodeLyoko.TowerBase.blockID);
		world.setBlock(i + 4, j + 14, k + 6, CodeLyoko.TowerBlock.blockID);
		world.setBlock(i + 4, j + 15, k + 0, CodeLyoko.TowerBlock.blockID);
		world.setBlock(i + 4, j + 15, k + 1, CodeLyoko.DigitalSeaBlock.blockID);
		world.setBlock(i + 4, j + 15, k + 5, CodeLyoko.DigitalSeaBlock.blockID);
		world.setBlock(i + 4, j + 15, k + 6, CodeLyoko.TowerBlock.blockID);
		world.setBlock(i + 4, j + 16, k + 0, CodeLyoko.TowerBlock.blockID);
		world.setBlock(i + 4, j + 16, k + 1, CodeLyoko.TowerBase.blockID);
		world.setBlock(i + 4, j + 16, k + 2, CodeLyoko.TowerBase.blockID);
		world.setBlock(i + 4, j + 16, k + 3, CodeLyoko.TowerBase.blockID);
		world.setBlock(i + 4, j + 16, k + 4, CodeLyoko.TowerBase.blockID);
		world.setBlock(i + 4, j + 16, k + 5, CodeLyoko.TowerBase.blockID);
		world.setBlock(i + 4, j + 16, k + 6, CodeLyoko.TowerBlock.blockID);
		world.setBlock(i + 4, j + 17, k + 1, CodeLyoko.TowerBlock.blockID);
		world.setBlock(i + 4, j + 17, k + 2, CodeLyoko.TowerBlock.blockID);
		world.setBlock(i + 4, j + 17, k + 3, CodeLyoko.TowerBlock.blockID);
		world.setBlock(i + 4, j + 17, k + 4, CodeLyoko.TowerBlock.blockID);
		world.setBlock(i + 4, j + 17, k + 5, CodeLyoko.TowerBlock.blockID);
		world.setBlock(i + 5, j + 0, k + 0, CodeLyoko.TowerBase.blockID);
		world.setBlock(i + 5, j + 0, k + 1, CodeLyoko.TowerBase.blockID);
		world.setBlock(i + 5, j + 0, k + 2, CodeLyoko.TowerBase.blockID);
		world.setBlock(i + 5, j + 0, k + 3, CodeLyoko.TowerBase.blockID);
		world.setBlock(i + 5, j + 0, k + 4, CodeLyoko.TowerBase.blockID);
		world.setBlock(i + 5, j + 0, k + 5, CodeLyoko.TowerBase.blockID);
		world.setBlock(i + 5, j + 0, k + 6, CodeLyoko.TowerBase.blockID);
		world.setBlock(i + 5, j + 1, k + 0, CodeLyoko.TowerBase.blockID);
		world.setBlock(i + 5, j + 1, k + 6, CodeLyoko.TowerBase.blockID);
		world.setBlock(i + 5, j + 2, k + 0, CodeLyoko.TowerBase.blockID);
		world.setBlock(i + 5, j + 2, k + 6, CodeLyoko.TowerBase.blockID);
		world.setBlock(i + 5, j + 3, k + 0, CodeLyoko.TowerBase.blockID);
		world.setBlock(i + 5, j + 3, k + 6, CodeLyoko.TowerBase.blockID);
		world.setBlock(i + 5, j + 4, k + 0, CodeLyoko.TowerBase.blockID);
		world.setBlock(i + 5, j + 4, k + 3, Block.blockLapis.blockID);
		world.setBlock(i + 5, j + 4, k + 6, CodeLyoko.TowerBase.blockID);
		world.setBlock(i + 5, j + 5, k + 0, CodeLyoko.TowerBase.blockID);
		world.setBlock(i + 5, j + 5, k + 6, CodeLyoko.TowerBase.blockID);
		world.setBlock(i + 5, j + 6, k + 0, CodeLyoko.TowerBase.blockID);
		world.setBlock(i + 5, j + 6, k + 6, CodeLyoko.TowerBase.blockID);
		world.setBlock(i + 5, j + 7, k + 0, CodeLyoko.TowerBase.blockID);
		world.setBlock(i + 5, j + 7, k + 6, CodeLyoko.TowerBase.blockID);
		world.setBlock(i + 5, j + 8, k + 0, CodeLyoko.TowerBlock.blockID);
		world.setBlock(i + 5, j + 8, k + 1, CodeLyoko.DigitalSeaBlock.blockID);
		world.setBlock(i + 5, j + 8, k + 2, CodeLyoko.TowerBase.blockID);
		world.setBlock(i + 5, j + 8, k + 3, CodeLyoko.DigitalSeaBlock.blockID);
		world.setBlock(i + 5, j + 8, k + 4, CodeLyoko.TowerBase.blockID);
		world.setBlock(i + 5, j + 8, k + 5, CodeLyoko.DigitalSeaBlock.blockID);
		world.setBlock(i + 5, j + 8, k + 6, CodeLyoko.TowerBlock.blockID);
		world.setBlock(i + 5, j + 9, k + 0, CodeLyoko.TowerBlock.blockID);
		world.setBlock(i + 5, j + 9, k + 2, CodeLyoko.DigitalSeaBlock.blockID);
		world.setBlock(i + 5, j + 9, k + 3, CodeLyoko.TowerBase.blockID);
		world.setBlock(i + 5, j + 9, k + 4, CodeLyoko.DigitalSeaBlock.blockID);
		world.setBlock(i + 5, j + 9, k + 6, CodeLyoko.TowerBlock.blockID);
		world.setBlock(i + 5, j + 10, k + 0, CodeLyoko.TowerBlock.blockID);
		world.setBlock(i + 5, j + 10, k + 1, CodeLyoko.DigitalSeaBlock.blockID);
		world.setBlock(i + 5, j + 10, k + 2, CodeLyoko.TowerBase.blockID);
		world.setBlock(i + 5, j + 10, k + 3, CodeLyoko.DigitalSeaBlock.blockID);
		world.setBlock(i + 5, j + 10, k + 4, CodeLyoko.TowerBase.blockID);
		world.setBlock(i + 5, j + 10, k + 5, CodeLyoko.DigitalSeaBlock.blockID);
		world.setBlock(i + 5, j + 10, k + 6, CodeLyoko.TowerBlock.blockID);
		world.setBlock(i + 5, j + 11, k + 0, CodeLyoko.TowerBlock.blockID);
		world.setBlock(i + 5, j + 11, k + 2, CodeLyoko.DigitalSeaBlock.blockID);
		world.setBlock(i + 5, j + 11, k + 3, CodeLyoko.TowerBase.blockID);
		world.setBlock(i + 5, j + 11, k + 4, CodeLyoko.DigitalSeaBlock.blockID);
		world.setBlock(i + 5, j + 11, k + 6, CodeLyoko.TowerBlock.blockID);
		world.setBlock(i + 5, j + 12, k + 0, CodeLyoko.TowerBlock.blockID);
		world.setBlock(i + 5, j + 12, k + 1, CodeLyoko.DigitalSeaBlock.blockID);
		world.setBlock(i + 5, j + 12, k + 2, CodeLyoko.TowerBase.blockID);
		world.setBlock(i + 5, j + 12, k + 3, CodeLyoko.DigitalSeaBlock.blockID);
		world.setBlock(i + 5, j + 12, k + 4, CodeLyoko.TowerBase.blockID);
		world.setBlock(i + 5, j + 12, k + 5, CodeLyoko.DigitalSeaBlock.blockID);
		world.setBlock(i + 5, j + 12, k + 6, CodeLyoko.TowerBlock.blockID);
		world.setBlock(i + 5, j + 13, k + 0, CodeLyoko.TowerBlock.blockID);
		world.setBlock(i + 5, j + 13, k + 2, CodeLyoko.DigitalSeaBlock.blockID);
		world.setBlock(i + 5, j + 13, k + 3, CodeLyoko.TowerBase.blockID);
		world.setBlock(i + 5, j + 13, k + 4, CodeLyoko.DigitalSeaBlock.blockID);
		world.setBlock(i + 5, j + 13, k + 6, CodeLyoko.TowerBlock.blockID);
		world.setBlock(i + 5, j + 14, k + 0, CodeLyoko.TowerBlock.blockID);
		world.setBlock(i + 5, j + 14, k + 1, CodeLyoko.DigitalSeaBlock.blockID);
		world.setBlock(i + 5, j + 14, k + 2, CodeLyoko.TowerBase.blockID);
		world.setBlock(i + 5, j + 14, k + 3, CodeLyoko.DigitalSeaBlock.blockID);
		world.setBlock(i + 5, j + 14, k + 4, CodeLyoko.TowerBase.blockID);
		world.setBlock(i + 5, j + 14, k + 5, CodeLyoko.DigitalSeaBlock.blockID);
		world.setBlock(i + 5, j + 14, k + 6, CodeLyoko.TowerBlock.blockID);
		world.setBlock(i + 5, j + 15, k + 0, CodeLyoko.TowerBlock.blockID);
		world.setBlock(i + 5, j + 15, k + 1, CodeLyoko.TowerBase.blockID);
		world.setBlock(i + 5, j + 15, k + 2, CodeLyoko.DigitalSeaBlock.blockID);
		world.setBlock(i + 5, j + 15, k + 3, CodeLyoko.TowerBase.blockID);
		world.setBlock(i + 5, j + 15, k + 4, CodeLyoko.DigitalSeaBlock.blockID);
		world.setBlock(i + 5, j + 15, k + 5, CodeLyoko.TowerBase.blockID);
		world.setBlock(i + 5, j + 15, k + 6, CodeLyoko.TowerBlock.blockID);
		world.setBlock(i + 5, j + 16, k + 0, CodeLyoko.TowerBlock.blockID);
		world.setBlock(i + 5, j + 16, k + 1, CodeLyoko.TowerBase.blockID);
		world.setBlock(i + 5, j + 16, k + 2, CodeLyoko.TowerBase.blockID);
		world.setBlock(i + 5, j + 16, k + 3, CodeLyoko.TowerBase.blockID);
		world.setBlock(i + 5, j + 16, k + 4, CodeLyoko.TowerBase.blockID);
		world.setBlock(i + 5, j + 16, k + 5, CodeLyoko.TowerBase.blockID);
		world.setBlock(i + 5, j + 16, k + 6, CodeLyoko.TowerBlock.blockID);
		world.setBlock(i + 5, j + 17, k + 1, CodeLyoko.TowerBlock.blockID);
		world.setBlock(i + 5, j + 17, k + 2, CodeLyoko.TowerBlock.blockID);
		world.setBlock(i + 5, j + 17, k + 3, CodeLyoko.TowerBlock.blockID);
		world.setBlock(i + 5, j + 17, k + 4, CodeLyoko.TowerBlock.blockID);
		world.setBlock(i + 5, j + 17, k + 5, CodeLyoko.TowerBlock.blockID);
		world.setBlock(i + 6, j + 0, k + 1, CodeLyoko.TowerBase.blockID);
		world.setBlock(i + 6, j + 0, k + 2, CodeLyoko.TowerBase.blockID);
		world.setBlock(i + 6, j + 0, k + 3, CodeLyoko.TowerBase.blockID);
		world.setBlock(i + 6, j + 0, k + 4, CodeLyoko.TowerBase.blockID);
		world.setBlock(i + 6, j + 0, k + 5, CodeLyoko.TowerBase.blockID);
		world.setBlock(i + 6, j + 1, k + 1, CodeLyoko.TowerBase.blockID);
		world.setBlock(i + 6, j + 1, k + 2, CodeLyoko.TowerBase.blockID);
		world.setBlock(i + 6, j + 1, k + 3, CodeLyoko.TowerBase.blockID);
		world.setBlock(i + 6, j + 1, k + 4, CodeLyoko.TowerBase.blockID);
		world.setBlock(i + 6, j + 1, k + 5, CodeLyoko.TowerBase.blockID);
		world.setBlock(i + 6, j + 2, k + 1, CodeLyoko.TowerBase.blockID);
		world.setBlock(i + 6, j + 2, k + 2, CodeLyoko.TowerBase.blockID);
		world.setBlock(i + 6, j + 2, k + 3, CodeLyoko.TowerBase.blockID);
		world.setBlock(i + 6, j + 2, k + 4, CodeLyoko.TowerBase.blockID);
		world.setBlock(i + 6, j + 2, k + 5, CodeLyoko.TowerBase.blockID);
		world.setBlock(i + 6, j + 3, k + 1, CodeLyoko.TowerBase.blockID);
		world.setBlock(i + 6, j + 3, k + 2, CodeLyoko.TowerBase.blockID);
		world.setBlock(i + 6, j + 3, k + 3, CodeLyoko.TowerBase.blockID);
		world.setBlock(i + 6, j + 3, k + 4, CodeLyoko.TowerBase.blockID);
		world.setBlock(i + 6, j + 3, k + 5, CodeLyoko.TowerBase.blockID);
		world.setBlock(i + 6, j + 4, k + 1, CodeLyoko.TowerBase.blockID);
		world.setBlock(i + 6, j + 4, k + 2, CodeLyoko.TowerBase.blockID);
		world.setBlock(i + 6, j + 4, k + 3, CodeLyoko.TowerBase.blockID);
		world.setBlock(i + 6, j + 4, k + 4, CodeLyoko.TowerBase.blockID);
		world.setBlock(i + 6, j + 4, k + 5, CodeLyoko.TowerBase.blockID);
		world.setBlock(i + 6, j + 5, k + 1, CodeLyoko.TowerBase.blockID);
		world.setBlock(i + 6, j + 5, k + 2, CodeLyoko.TowerBase.blockID);
		world.setBlock(i + 6, j + 5, k + 4, CodeLyoko.TowerBase.blockID);
		world.setBlock(i + 6, j + 5, k + 5, CodeLyoko.TowerBase.blockID);
		world.setBlock(i + 6, j + 6, k + 1, CodeLyoko.TowerBase.blockID);
		world.setBlock(i + 6, j + 6, k + 2, CodeLyoko.TowerBase.blockID);
		world.setBlock(i + 6, j + 6, k + 4, CodeLyoko.TowerBase.blockID);
		world.setBlock(i + 6, j + 6, k + 5, CodeLyoko.TowerBase.blockID);
		world.setBlock(i + 6, j + 7, k + 1, CodeLyoko.TowerBase.blockID);
		world.setBlock(i + 6, j + 7, k + 2, CodeLyoko.TowerBase.blockID);
		world.setBlock(i + 6, j + 7, k + 3, CodeLyoko.TowerBase.blockID);
		world.setBlock(i + 6, j + 7, k + 4, CodeLyoko.TowerBase.blockID);
		world.setBlock(i + 6, j + 7, k + 5, CodeLyoko.TowerBase.blockID);
		world.setBlock(i + 6, j + 8, k + 1, CodeLyoko.TowerBlock.blockID);
		world.setBlock(i + 6, j + 8, k + 2, CodeLyoko.TowerBlock.blockID);
		world.setBlock(i + 6, j + 8, k + 3, CodeLyoko.TowerBlock.blockID);
		world.setBlock(i + 6, j + 8, k + 4, CodeLyoko.TowerBlock.blockID);
		world.setBlock(i + 6, j + 8, k + 5, CodeLyoko.TowerBlock.blockID);
		world.setBlock(i + 6, j + 9, k + 1, CodeLyoko.TowerBlock.blockID);
		world.setBlock(i + 6, j + 9, k + 2, CodeLyoko.TowerBlock.blockID);
		world.setBlock(i + 6, j + 9, k + 3, CodeLyoko.TowerBlock.blockID);
		world.setBlock(i + 6, j + 9, k + 4, CodeLyoko.TowerBlock.blockID);
		world.setBlock(i + 6, j + 9, k + 5, CodeLyoko.TowerBlock.blockID);
		world.setBlock(i + 6, j + 10, k + 1, CodeLyoko.TowerBlock.blockID);
		world.setBlock(i + 6, j + 10, k + 2, CodeLyoko.TowerBlock.blockID);
		world.setBlock(i + 6, j + 10, k + 3, CodeLyoko.TowerBlock.blockID);
		world.setBlock(i + 6, j + 10, k + 4, CodeLyoko.TowerBlock.blockID);
		world.setBlock(i + 6, j + 10, k + 5, CodeLyoko.TowerBlock.blockID);
		world.setBlock(i + 6, j + 11, k + 1, CodeLyoko.TowerBlock.blockID);
		world.setBlock(i + 6, j + 11, k + 2, CodeLyoko.TowerBlock.blockID);
		world.setBlock(i + 6, j + 11, k + 3, CodeLyoko.TowerBlock.blockID);
		world.setBlock(i + 6, j + 11, k + 4, CodeLyoko.TowerBlock.blockID);
		world.setBlock(i + 6, j + 11, k + 5, CodeLyoko.TowerBlock.blockID);
		world.setBlock(i + 6, j + 12, k + 1, CodeLyoko.TowerBlock.blockID);
		world.setBlock(i + 6, j + 12, k + 2, CodeLyoko.TowerBlock.blockID);
		world.setBlock(i + 6, j + 12, k + 3, CodeLyoko.TowerBlock.blockID);
		world.setBlock(i + 6, j + 12, k + 4, CodeLyoko.TowerBlock.blockID);
		world.setBlock(i + 6, j + 12, k + 5, CodeLyoko.TowerBlock.blockID);
		world.setBlock(i + 6, j + 13, k + 1, CodeLyoko.TowerBlock.blockID);
		world.setBlock(i + 6, j + 13, k + 2, CodeLyoko.TowerBlock.blockID);
		world.setBlock(i + 6, j + 13, k + 3, CodeLyoko.TowerBlock.blockID);
		world.setBlock(i + 6, j + 13, k + 4, CodeLyoko.TowerBlock.blockID);
		world.setBlock(i + 6, j + 13, k + 5, CodeLyoko.TowerBlock.blockID);
		world.setBlock(i + 6, j + 14, k + 1, CodeLyoko.TowerBlock.blockID);
		world.setBlock(i + 6, j + 14, k + 2, CodeLyoko.TowerBlock.blockID);
		world.setBlock(i + 6, j + 14, k + 3, CodeLyoko.TowerBlock.blockID);
		world.setBlock(i + 6, j + 14, k + 4, CodeLyoko.TowerBlock.blockID);
		world.setBlock(i + 6, j + 14, k + 5, CodeLyoko.TowerBlock.blockID);
		world.setBlock(i + 6, j + 15, k + 1, CodeLyoko.TowerBlock.blockID);
		world.setBlock(i + 6, j + 15, k + 2, CodeLyoko.TowerBlock.blockID);
		world.setBlock(i + 6, j + 15, k + 3, CodeLyoko.TowerBlock.blockID);
		world.setBlock(i + 6, j + 15, k + 4, CodeLyoko.TowerBlock.blockID);
		world.setBlock(i + 6, j + 15, k + 5, CodeLyoko.TowerBlock.blockID);
		world.setBlock(i + 6, j + 16, k + 1, CodeLyoko.TowerBlock.blockID);
		world.setBlock(i + 6, j + 16, k + 2, CodeLyoko.TowerBlock.blockID);
		world.setBlock(i + 6, j + 16, k + 3, CodeLyoko.TowerBlock.blockID);
		world.setBlock(i + 6, j + 16, k + 4, CodeLyoko.TowerBlock.blockID);
		world.setBlock(i + 6, j + 16, k + 5, CodeLyoko.TowerBlock.blockID);
		
		return true;
	}
}